# 09_supervision

# Домашнее задание к занятию «10. Coroutines: Scopes, Cancellation, Supervision»

Выполненное задание прикрепите ссылкой на ваши GitHub-проекты в личном кабинете студента на сайте [netology.ru](https://netology.ru).

## Вопросы: Cancellation

### Вопрос №1

Отработает ли в этом коде строка `<--`? Поясните, почему да или нет.

```kotlin
fun main() = runBlocking {
    val job = CoroutineScope(EmptyCoroutineContext).launch {
        launch {
            delay(500)
            println("ok") // <--
        }
        launch {
            delay(500)
            println("ok")
        }
    }
    delay(100)
    job.cancelAndJoin()
}
```
Ответ: Нет, т.к. задержка основной корутины меньше чем дочерних, а основная находится в состоянии отмены(job.cancelAndJoin())

### Вопрос №2

Отработает ли в этом коде строка `<--`. Поясните, почему да или нет.

```kotlin
fun main() = runBlocking {
    val job = CoroutineScope(EmptyCoroutineContext).launch {
        val child = launch {
            delay(500)
            println("ok") // <--
        }
        launch {
            delay(500)
            println("ok")
        }
        delay(100)
        child.cancel()
    }
    delay(100)
    job.join()
}
```
Ответ: Нет, хоть и основная корутина готова ждать благодаря job.join(), но в job вызван метод child.cancel() и задержка меньше чем в child.

## Вопросы: Exception Handling

### Вопрос №1

Отработает ли в этом коде строка `<--`. Поясните, почему да или нет.

```kotlin
fun main() {
    with(CoroutineScope(EmptyCoroutineContext)) {
        try {
            launch {
                throw Exception("something bad happened")
            }
        } catch (e: Exception) {
            e.printStackTrace() // <--
        }
    }
    Thread.sleep(1000)
}
```
Ответ: Нет, т.к. корутина запускается внутри оператора Try/Catch.

### Вопрос №2

Отработает ли в этом коде строка `<--`. Поясните, почему да или нет.

```kotlin
fun main() {
    CoroutineScope(EmptyCoroutineContext).launch {
        try {
            coroutineScope {
                throw Exception("something bad happened")
            }
        } catch (e: Exception) {
            e.printStackTrace() // <--
        }
    }
    Thread.sleep(1000)
}
```
Ответ: Да, благодаря функции coroutineScope, которая позволяет перехватывать исключения.

### Вопрос №3

Отработает ли в этом коде строка `<--`. Поясните, почему да или нет.

```kotlin
fun main() {
    CoroutineScope(EmptyCoroutineContext).launch {
        try {
            supervisorScope {
                throw Exception("something bad happened")
            }
        } catch (e: Exception) {
            e.printStackTrace() // <--
        }
    }
    Thread.sleep(1000)
}
```
Ответ: Да, по аналогии с функцией coroutineScope.

### Вопрос №4

Отработает ли в этом коде строка `<--`. Поясните, почему да или нет.

```kotlin
fun main() {
    CoroutineScope(EmptyCoroutineContext).launch {
        try {
            coroutineScope {
                launch {
                    delay(500)
                    throw Exception("something bad happened") // <--
                }
                launch {
                    throw Exception("something bad happened")
                }
            }
        } catch (e: Exception) {
            e.printStackTrace()
        }
    }
    Thread.sleep(1000)
}
```
Ответ: Нет, т.к. у первой корутиный стоит задержка, вторая срабатывает раньше и выбрасывается исключение, а первая корутина отменяется потому что используется функция coroutineScope.

### Вопрос №5

Отработает ли в этом коде строка `<--`. Поясните, почему да или нет.

```kotlin
fun main() {
    CoroutineScope(EmptyCoroutineContext).launch {
        try {
            supervisorScope {
                launch {
                    delay(500)
                    throw Exception("something bad happened") // <--
                }
                launch {
                    throw Exception("something bad happened")
                }
            }
        } catch (e: Exception) {
            e.printStackTrace() // <--
        }
    }
    Thread.sleep(1000)
}
```
Ответ: Да, благодаря функции supervisorScope, исключение возникшее в одной корутине, не повлияет на выполнение другой.

### Вопрос №6

Отработает ли в этом коде строка `<--`. Поясните, почему да или нет.

```kotlin
fun main() {
    CoroutineScope(EmptyCoroutineContext).launch {
        CoroutineScope(EmptyCoroutineContext).launch {
            launch {
                delay(1000)
                println("ok") // <--
            }
            launch {
                delay(500)
                println("ok")
            }
            throw Exception("something bad happened")
        }
    }
    Thread.sleep(1000)
}
```
Ответ: Нет, т.к. в дочерних корутинах стоит задержка, а родительская выбрасывает исключение.

### Вопрос №7

Отработает ли в этом коде строка `<--`. Поясните, почему да или нет.

```kotlin
fun main() {
    CoroutineScope(EmptyCoroutineContext).launch {
        CoroutineScope(EmptyCoroutineContext + SupervisorJob()).launch {
            launch {
                delay(1000)
                println("ok") // <--
            }
            launch {
                delay(500)
                println("ok")
            }
            throw Exception("something bad happened")
        }
    }
    Thread.sleep(1000)
}
```
Ответ: Нет, благодаря SupervisorJob(), отменяются дочерние корутины т.к. отменилась родительская.
